<?xml version="1.0" encoding="UTF-8"?>
<testng-results ignored="0" total="3" passed="2" failed="1" skipped="0">
  <reporter-output>
  </reporter-output>
  <suite started-at="2023-04-28T16:27:51 IST" name="Suite" finished-at="2023-04-28T16:29:32 IST" duration-ms="101209">
    <groups>
    </groups>
    <test started-at="2023-04-28T16:27:51 IST" name="Test" finished-at="2023-04-28T16:29:32 IST" duration-ms="101209">
      <class name="test.Sign_up_test">
        <test-method is-config="true" signature="lunch(java.lang.String,java.lang.String)[pri:0, instance:test.Sign_up_test@1ed6388a]" started-at="2023-04-28T16:27:51 IST" name="lunch" finished-at="2023-04-28T16:27:58 IST" duration-ms="7107" status="PASS">
          <params>
            <param index="0">
              <value>
                <![CDATA[chrome]]>
              </value>
            </param>
            <param index="1">
              <value>
                <![CDATA[Stage]]>
              </value>
            </param>
          </params>
          <reporter-output>
          </reporter-output>
        </test-method> <!-- lunch -->
        <test-method signature="Sign_up_first()[pri:1, instance:test.Sign_up_test@1ed6388a]" started-at="2023-04-28T16:27:58 IST" name="Sign_up_first" finished-at="2023-04-28T16:28:18 IST" duration-ms="19988" status="PASS">
          <reporter-output>
          </reporter-output>
        </test-method> <!-- Sign_up_first -->
        <test-method signature="sign_up_second_page()[pri:2, instance:test.Sign_up_test@1ed6388a]" started-at="2023-04-28T16:28:18 IST" name="sign_up_second_page" finished-at="2023-04-28T16:28:25 IST" duration-ms="7298" status="PASS">
          <reporter-output>
          </reporter-output>
        </test-method> <!-- sign_up_second_page -->
        <test-method signature="third_page_sign_up()[pri:3, instance:test.Sign_up_test@1ed6388a]" started-at="2023-04-28T16:28:25 IST" name="third_page_sign_up" finished-at="2023-04-28T16:29:31 IST" duration-ms="65688" status="FAIL">
          <exception class="java.lang.AssertionError">
            <message>
              <![CDATA[expected [Account Application
Sucessfully Submitted!] but found [Account Application
Sucessfully Submitted!]]]>
            </message>
            <full-stacktrace>
              <![CDATA[java.lang.AssertionError: expected [Account Application
Sucessfully Submitted!] but found [Account Application
Sucessfully Submitted!]
at org.testng.Assert.fail(Assert.java:99)
at org.testng.Assert.failNotEquals(Assert.java:1037)
at org.testng.Assert.assertEqualsImpl(Assert.java:140)
at org.testng.Assert.assertEquals(Assert.java:122)
at org.testng.Assert.assertEquals(Assert.java:629)
at org.testng.Assert.assertEquals(Assert.java:639)
at test.Sign_up_test.third_page_sign_up(Sign_up_test.java:69)
at java.base/jdk.internal.reflect.DirectMethodHandleAccessor.invoke(DirectMethodHandleAccessor.java:104)
at java.base/java.lang.reflect.Method.invoke(Method.java:578)
at org.testng.internal.MethodInvocationHelper.invokeMethod(MethodInvocationHelper.java:133)
at org.testng.internal.TestInvoker.invokeMethod(TestInvoker.java:598)
at org.testng.internal.TestInvoker.invokeTestMethod(TestInvoker.java:173)
at org.testng.internal.MethodRunner.runInSequence(MethodRunner.java:46)
at org.testng.internal.TestInvoker$MethodInvocationAgent.invoke(TestInvoker.java:824)
at org.testng.internal.TestInvoker.invokeTestMethods(TestInvoker.java:146)
at org.testng.internal.TestMethodWorker.invokeTestMethods(TestMethodWorker.java:146)
at org.testng.internal.TestMethodWorker.run(TestMethodWorker.java:128)
at java.base/java.util.ArrayList.forEach(ArrayList.java:1511)
at org.testng.TestRunner.privateRun(TestRunner.java:794)
at org.testng.TestRunner.run(TestRunner.java:596)
at org.testng.SuiteRunner.runTest(SuiteRunner.java:377)
at org.testng.SuiteRunner.runSequentially(SuiteRunner.java:371)
at org.testng.SuiteRunner.privateRun(SuiteRunner.java:332)
at org.testng.SuiteRunner.run(SuiteRunner.java:276)
at org.testng.SuiteRunnerWorker.runSuite(SuiteRunnerWorker.java:53)
at org.testng.SuiteRunnerWorker.run(SuiteRunnerWorker.java:96)
at org.testng.TestNG.runSuitesSequentially(TestNG.java:1212)
at org.testng.TestNG.runSuitesLocally(TestNG.java:1134)
at org.testng.TestNG.runSuites(TestNG.java:1063)
at org.testng.TestNG.run(TestNG.java:1031)
at org.testng.remote.AbstractRemoteTestNG.run(AbstractRemoteTestNG.java:115)
at org.testng.remote.RemoteTestNG.initAndRun(RemoteTestNG.java:251)
at org.testng.remote.RemoteTestNG.main(RemoteTestNG.java:77)
]]>
            </full-stacktrace>
          </exception> <!-- java.lang.AssertionError -->
          <reporter-output>
          </reporter-output>
        </test-method> <!-- third_page_sign_up -->
        <test-method is-config="true" signature="quit()[pri:0, instance:test.Sign_up_test@1ed6388a]" started-at="2023-04-28T16:29:31 IST" name="quit" finished-at="2023-04-28T16:29:32 IST" duration-ms="1079" status="PASS">
          <reporter-output>
          </reporter-output>
        </test-method> <!-- quit -->
      </class> <!-- test.Sign_up_test -->
    </test> <!-- Test -->
  </suite> <!-- Suite -->
</testng-results>
